2025-09-18 22:38:02 - error_logger - ERROR - Error with context: {"timestamp":"2025-09-18T19:08:02.341296","error_type":"TypeError","error_message":"connect() got an unexpected keyword argument 'pool_pre_ping'","context":{"method":"initialize_database"}}
Traceback (most recent call last):
  File "C:\Users\victus\Desktop\Main3.2\general\Database\MySQL\db_manager.py", line 29, in initialize
    self.pool = await aiomysql.create_pool(
                ^^^^^^^^^^^^^^^^^^^^^^^^^^^
    ...<16 lines>...
    )
    ^
  File "C:\Users\victus\AppData\Local\Packages\PythonSoftwareFoundation.Python.3.13_qbz5n2kfra8p0\LocalCache\local-packages\Python313\site-packages\aiomysql\pool.py", line 29, in _create_pool
    await pool._fill_free_pool(False)
  File "C:\Users\victus\AppData\Local\Packages\PythonSoftwareFoundation.Python.3.13_qbz5n2kfra8p0\LocalCache\local-packages\Python313\site-packages\aiomysql\pool.py", line 182, in _fill_free_pool
    conn = await connect(echo=self._echo, loop=self._loop,
                 ~~~~~~~^^^^^^^^^^^^^^^^^^^^^^^^^^^^^^^^^^
                         **self._conn_kwargs)
                         ^^^^^^^^^^^^^^^^^^^^
TypeError: connect() got an unexpected keyword argument 'pool_pre_ping'
2025-09-18 22:38:02 - error_logger - ERROR - Error with context: {"timestamp":"2025-09-18T19:08:02.347863","error_type":"TypeError","error_message":"connect() got an unexpected keyword argument 'pool_pre_ping'","context":{"phase":"initialization"}}
Traceback (most recent call last):
  File "C:\Users\victus\Desktop\Main3.2\main.py", line 51, in initialize
    await self.db.initialize()
  File "C:\Users\victus\Desktop\Main3.2\general\Database\MySQL\db_manager.py", line 29, in initialize
    self.pool = await aiomysql.create_pool(
                ^^^^^^^^^^^^^^^^^^^^^^^^^^^
    ...<16 lines>...
    )
    ^
  File "C:\Users\victus\AppData\Local\Packages\PythonSoftwareFoundation.Python.3.13_qbz5n2kfra8p0\LocalCache\local-packages\Python313\site-packages\aiomysql\pool.py", line 29, in _create_pool
    await pool._fill_free_pool(False)
  File "C:\Users\victus\AppData\Local\Packages\PythonSoftwareFoundation.Python.3.13_qbz5n2kfra8p0\LocalCache\local-packages\Python313\site-packages\aiomysql\pool.py", line 182, in _fill_free_pool
    conn = await connect(echo=self._echo, loop=self._loop,
                 ~~~~~~~^^^^^^^^^^^^^^^^^^^^^^^^^^^^^^^^^^
                         **self._conn_kwargs)
                         ^^^^^^^^^^^^^^^^^^^^
TypeError: connect() got an unexpected keyword argument 'pool_pre_ping'
2025-09-18 22:40:00 - error_logger - ERROR - Error with context: {"timestamp":"2025-09-18T19:10:00.533415","error_type":"TypeError","error_message":"connect() got an unexpected keyword argument 'read_timeout'","context":{"method":"initialize_database"}}
Traceback (most recent call last):
  File "C:\Users\victus\Desktop\Main3.2\general\Database\MySQL\db_manager.py", line 29, in initialize
    self.pool = await aiomysql.create_pool(
                ^^^^^^^^^^^^^^^^^^^^^^^^^^^
    ...<16 lines>...
    )
    ^
  File "C:\Users\victus\AppData\Local\Packages\PythonSoftwareFoundation.Python.3.13_qbz5n2kfra8p0\LocalCache\local-packages\Python313\site-packages\aiomysql\pool.py", line 29, in _create_pool
    await pool._fill_free_pool(False)
  File "C:\Users\victus\AppData\Local\Packages\PythonSoftwareFoundation.Python.3.13_qbz5n2kfra8p0\LocalCache\local-packages\Python313\site-packages\aiomysql\pool.py", line 182, in _fill_free_pool
    conn = await connect(echo=self._echo, loop=self._loop,
                 ~~~~~~~^^^^^^^^^^^^^^^^^^^^^^^^^^^^^^^^^^
                         **self._conn_kwargs)
                         ^^^^^^^^^^^^^^^^^^^^
TypeError: connect() got an unexpected keyword argument 'read_timeout'
2025-09-18 22:40:00 - error_logger - ERROR - Error with context: {"timestamp":"2025-09-18T19:10:00.539039","error_type":"TypeError","error_message":"connect() got an unexpected keyword argument 'read_timeout'","context":{"phase":"initialization"}}
Traceback (most recent call last):
  File "C:\Users\victus\Desktop\Main3.2\main.py", line 51, in initialize
    await self.db.initialize()
  File "C:\Users\victus\Desktop\Main3.2\general\Database\MySQL\db_manager.py", line 29, in initialize
    self.pool = await aiomysql.create_pool(
                ^^^^^^^^^^^^^^^^^^^^^^^^^^^
    ...<16 lines>...
    )
    ^
  File "C:\Users\victus\AppData\Local\Packages\PythonSoftwareFoundation.Python.3.13_qbz5n2kfra8p0\LocalCache\local-packages\Python313\site-packages\aiomysql\pool.py", line 29, in _create_pool
    await pool._fill_free_pool(False)
  File "C:\Users\victus\AppData\Local\Packages\PythonSoftwareFoundation.Python.3.13_qbz5n2kfra8p0\LocalCache\local-packages\Python313\site-packages\aiomysql\pool.py", line 182, in _fill_free_pool
    conn = await connect(echo=self._echo, loop=self._loop,
                 ~~~~~~~^^^^^^^^^^^^^^^^^^^^^^^^^^^^^^^^^^
                         **self._conn_kwargs)
                         ^^^^^^^^^^^^^^^^^^^^
TypeError: connect() got an unexpected keyword argument 'read_timeout'
2025-09-18 22:43:48 - error_logger - ERROR - Error with context: {"timestamp":"2025-09-18T19:13:48.679063","error_type":"TypeError","error_message":"connect() got an unexpected keyword argument 'pool_timeout'","context":{"method":"initialize_database"}}
Traceback (most recent call last):
  File "C:\Users\victus\Desktop\Main3.2\general\Database\MySQL\db_manager.py", line 29, in initialize
    self.pool = await aiomysql.create_pool(
                ^^^^^^^^^^^^^^^^^^^^^^^^^^^
    ...<16 lines>...
    )
    ^
  File "C:\Users\victus\AppData\Local\Packages\PythonSoftwareFoundation.Python.3.13_qbz5n2kfra8p0\LocalCache\local-packages\Python313\site-packages\aiomysql\pool.py", line 29, in _create_pool
    await pool._fill_free_pool(False)
  File "C:\Users\victus\AppData\Local\Packages\PythonSoftwareFoundation.Python.3.13_qbz5n2kfra8p0\LocalCache\local-packages\Python313\site-packages\aiomysql\pool.py", line 182, in _fill_free_pool
    conn = await connect(echo=self._echo, loop=self._loop,
                 ~~~~~~~^^^^^^^^^^^^^^^^^^^^^^^^^^^^^^^^^^
                         **self._conn_kwargs)
                         ^^^^^^^^^^^^^^^^^^^^
TypeError: connect() got an unexpected keyword argument 'pool_timeout'
2025-09-18 22:43:48 - error_logger - ERROR - Error with context: {"timestamp":"2025-09-18T19:13:48.681559","error_type":"TypeError","error_message":"connect() got an unexpected keyword argument 'pool_timeout'","context":{"phase":"initialization"}}
Traceback (most recent call last):
  File "C:\Users\victus\Desktop\Main3.2\main.py", line 51, in initialize
    await self.db.initialize()
  File "C:\Users\victus\Desktop\Main3.2\general\Database\MySQL\db_manager.py", line 29, in initialize
    self.pool = await aiomysql.create_pool(
                ^^^^^^^^^^^^^^^^^^^^^^^^^^^
    ...<16 lines>...
    )
    ^
  File "C:\Users\victus\AppData\Local\Packages\PythonSoftwareFoundation.Python.3.13_qbz5n2kfra8p0\LocalCache\local-packages\Python313\site-packages\aiomysql\pool.py", line 29, in _create_pool
    await pool._fill_free_pool(False)
  File "C:\Users\victus\AppData\Local\Packages\PythonSoftwareFoundation.Python.3.13_qbz5n2kfra8p0\LocalCache\local-packages\Python313\site-packages\aiomysql\pool.py", line 182, in _fill_free_pool
    conn = await connect(echo=self._echo, loop=self._loop,
                 ~~~~~~~^^^^^^^^^^^^^^^^^^^^^^^^^^^^^^^^^^
                         **self._conn_kwargs)
                         ^^^^^^^^^^^^^^^^^^^^
TypeError: connect() got an unexpected keyword argument 'pool_timeout'
2025-09-18 22:44:59 - error_logger - ERROR - Error with context: {"timestamp":"2025-09-18T19:14:59.102136","error_type":"OperationalError","error_message":"(2003, \"Can't connect to MySQL server on '127.0.0.1'\")","context":{"method":"initialize_database"}}
Traceback (most recent call last):
  File "C:\Users\victus\AppData\Local\Packages\PythonSoftwareFoundation.Python.3.13_qbz5n2kfra8p0\LocalCache\local-packages\Python313\site-packages\aiomysql\connection.py", line 527, in _connect
    self._reader, self._writer = await \
                                 ^^^^^^^
    ...<4 lines>...
            timeout=self.connect_timeout)
            ^^^^^^^^^^^^^^^^^^^^^^^^^^^^^
  File "C:\Program Files\WindowsApps\PythonSoftwareFoundation.Python.3.13_3.13.2032.0_x64__qbz5n2kfra8p0\Lib\asyncio\tasks.py", line 507, in wait_for
    return await fut
           ^^^^^^^^^
  File "C:\Users\victus\AppData\Local\Packages\PythonSoftwareFoundation.Python.3.13_qbz5n2kfra8p0\LocalCache\local-packages\Python313\site-packages\aiomysql\connection.py", line 88, in _open_connection
    transport, _ = await loop.create_connection(
                   ^^^^^^^^^^^^^^^^^^^^^^^^^^^^^
        lambda: protocol, host, port, **kwds)
        ^^^^^^^^^^^^^^^^^^^^^^^^^^^^^^^^^^^^^
  File "C:\Program Files\WindowsApps\PythonSoftwareFoundation.Python.3.13_3.13.2032.0_x64__qbz5n2kfra8p0\Lib\asyncio\base_events.py", line 1171, in create_connection
    raise exceptions[0]
  File "C:\Program Files\WindowsApps\PythonSoftwareFoundation.Python.3.13_3.13.2032.0_x64__qbz5n2kfra8p0\Lib\asyncio\base_events.py", line 1146, in create_connection
    sock = await self._connect_sock(
           ^^^^^^^^^^^^^^^^^^^^^^^^^
        exceptions, addrinfo, laddr_infos)
        ^^^^^^^^^^^^^^^^^^^^^^^^^^^^^^^^^^
  File "C:\Program Files\WindowsApps\PythonSoftwareFoundation.Python.3.13_3.13.2032.0_x64__qbz5n2kfra8p0\Lib\asyncio\base_events.py", line 1045, in _connect_sock
    await self.sock_connect(sock, address)
  File "C:\Program Files\WindowsApps\PythonSoftwareFoundation.Python.3.13_3.13.2032.0_x64__qbz5n2kfra8p0\Lib\asyncio\proactor_events.py", line 728, in sock_connect
    return await self._proactor.connect(sock, address)
           ^^^^^^^^^^^^^^^^^^^^^^^^^^^^^^^^^^^^^^^^^^^
  File "C:\Program Files\WindowsApps\PythonSoftwareFoundation.Python.3.13_3.13.2032.0_x64__qbz5n2kfra8p0\Lib\asyncio\windows_events.py", line 804, in _poll
    value = callback(transferred, key, ov)
  File "C:\Program Files\WindowsApps\PythonSoftwareFoundation.Python.3.13_3.13.2032.0_x64__qbz5n2kfra8p0\Lib\asyncio\windows_events.py", line 600, in finish_connect
    ov.getresult()
    ~~~~~~~~~~~~^^
ConnectionRefusedError: [WinError 1225] The remote computer refused the network connection

The above exception was the direct cause of the following exception:

Traceback (most recent call last):
  File "C:\Users\victus\Desktop\Main3.2\general\Database\MySQL\db_manager.py", line 29, in initialize
    self.pool = await aiomysql.create_pool(
                ^^^^^^^^^^^^^^^^^^^^^^^^^^^
    ...<16 lines>...
    )
    ^
  File "C:\Users\victus\AppData\Local\Packages\PythonSoftwareFoundation.Python.3.13_qbz5n2kfra8p0\LocalCache\local-packages\Python313\site-packages\aiomysql\pool.py", line 29, in _create_pool
    await pool._fill_free_pool(False)
  File "C:\Users\victus\AppData\Local\Packages\PythonSoftwareFoundation.Python.3.13_qbz5n2kfra8p0\LocalCache\local-packages\Python313\site-packages\aiomysql\pool.py", line 182, in _fill_free_pool
    conn = await connect(echo=self._echo, loop=self._loop,
           ^^^^^^^^^^^^^^^^^^^^^^^^^^^^^^^^^^^^^^^^^^^^^^^
                         **self._conn_kwargs)
                         ^^^^^^^^^^^^^^^^^^^^
  File "C:\Users\victus\AppData\Local\Packages\PythonSoftwareFoundation.Python.3.13_qbz5n2kfra8p0\LocalCache\local-packages\Python313\site-packages\aiomysql\connection.py", line 75, in _connect
    await conn._connect()
  File "C:\Users\victus\AppData\Local\Packages\PythonSoftwareFoundation.Python.3.13_qbz5n2kfra8p0\LocalCache\local-packages\Python313\site-packages\aiomysql\connection.py", line 563, in _connect
    raise OperationalError(
    ...<2 lines>...
    ) from e
pymysql.err.OperationalError: (2003, "Can't connect to MySQL server on '127.0.0.1'")
2025-09-18 22:44:59 - error_logger - ERROR - Error with context: {"timestamp":"2025-09-18T19:14:59.116599","error_type":"OperationalError","error_message":"(2003, \"Can't connect to MySQL server on '127.0.0.1'\")","context":{"phase":"initialization"}}
Traceback (most recent call last):
  File "C:\Users\victus\AppData\Local\Packages\PythonSoftwareFoundation.Python.3.13_qbz5n2kfra8p0\LocalCache\local-packages\Python313\site-packages\aiomysql\connection.py", line 527, in _connect
    self._reader, self._writer = await \
                                 ^^^^^^^
    ...<4 lines>...
            timeout=self.connect_timeout)
            ^^^^^^^^^^^^^^^^^^^^^^^^^^^^^
  File "C:\Program Files\WindowsApps\PythonSoftwareFoundation.Python.3.13_3.13.2032.0_x64__qbz5n2kfra8p0\Lib\asyncio\tasks.py", line 507, in wait_for
    return await fut
           ^^^^^^^^^
  File "C:\Users\victus\AppData\Local\Packages\PythonSoftwareFoundation.Python.3.13_qbz5n2kfra8p0\LocalCache\local-packages\Python313\site-packages\aiomysql\connection.py", line 88, in _open_connection
    transport, _ = await loop.create_connection(
                   ^^^^^^^^^^^^^^^^^^^^^^^^^^^^^
        lambda: protocol, host, port, **kwds)
        ^^^^^^^^^^^^^^^^^^^^^^^^^^^^^^^^^^^^^
  File "C:\Program Files\WindowsApps\PythonSoftwareFoundation.Python.3.13_3.13.2032.0_x64__qbz5n2kfra8p0\Lib\asyncio\base_events.py", line 1171, in create_connection
    raise exceptions[0]
  File "C:\Program Files\WindowsApps\PythonSoftwareFoundation.Python.3.13_3.13.2032.0_x64__qbz5n2kfra8p0\Lib\asyncio\base_events.py", line 1146, in create_connection
    sock = await self._connect_sock(
           ^^^^^^^^^^^^^^^^^^^^^^^^^
        exceptions, addrinfo, laddr_infos)
        ^^^^^^^^^^^^^^^^^^^^^^^^^^^^^^^^^^
  File "C:\Program Files\WindowsApps\PythonSoftwareFoundation.Python.3.13_3.13.2032.0_x64__qbz5n2kfra8p0\Lib\asyncio\base_events.py", line 1045, in _connect_sock
    await self.sock_connect(sock, address)
  File "C:\Program Files\WindowsApps\PythonSoftwareFoundation.Python.3.13_3.13.2032.0_x64__qbz5n2kfra8p0\Lib\asyncio\proactor_events.py", line 728, in sock_connect
    return await self._proactor.connect(sock, address)
           ^^^^^^^^^^^^^^^^^^^^^^^^^^^^^^^^^^^^^^^^^^^
  File "C:\Program Files\WindowsApps\PythonSoftwareFoundation.Python.3.13_3.13.2032.0_x64__qbz5n2kfra8p0\Lib\asyncio\windows_events.py", line 804, in _poll
    value = callback(transferred, key, ov)
  File "C:\Program Files\WindowsApps\PythonSoftwareFoundation.Python.3.13_3.13.2032.0_x64__qbz5n2kfra8p0\Lib\asyncio\windows_events.py", line 600, in finish_connect
    ov.getresult()
    ~~~~~~~~~~~~^^
ConnectionRefusedError: [WinError 1225] The remote computer refused the network connection

The above exception was the direct cause of the following exception:

Traceback (most recent call last):
  File "C:\Users\victus\Desktop\Main3.2\main.py", line 51, in initialize
    await self.db.initialize()
  File "C:\Users\victus\Desktop\Main3.2\general\Database\MySQL\db_manager.py", line 29, in initialize
    self.pool = await aiomysql.create_pool(
                ^^^^^^^^^^^^^^^^^^^^^^^^^^^
    ...<16 lines>...
    )
    ^
  File "C:\Users\victus\AppData\Local\Packages\PythonSoftwareFoundation.Python.3.13_qbz5n2kfra8p0\LocalCache\local-packages\Python313\site-packages\aiomysql\pool.py", line 29, in _create_pool
    await pool._fill_free_pool(False)
  File "C:\Users\victus\AppData\Local\Packages\PythonSoftwareFoundation.Python.3.13_qbz5n2kfra8p0\LocalCache\local-packages\Python313\site-packages\aiomysql\pool.py", line 182, in _fill_free_pool
    conn = await connect(echo=self._echo, loop=self._loop,
           ^^^^^^^^^^^^^^^^^^^^^^^^^^^^^^^^^^^^^^^^^^^^^^^
                         **self._conn_kwargs)
                         ^^^^^^^^^^^^^^^^^^^^
  File "C:\Users\victus\AppData\Local\Packages\PythonSoftwareFoundation.Python.3.13_qbz5n2kfra8p0\LocalCache\local-packages\Python313\site-packages\aiomysql\connection.py", line 75, in _connect
    await conn._connect()
  File "C:\Users\victus\AppData\Local\Packages\PythonSoftwareFoundation.Python.3.13_qbz5n2kfra8p0\LocalCache\local-packages\Python313\site-packages\aiomysql\connection.py", line 563, in _connect
    raise OperationalError(
    ...<2 lines>...
    ) from e
pymysql.err.OperationalError: (2003, "Can't connect to MySQL server on '127.0.0.1'")
2025-09-18 22:55:43 - error_logger - ERROR - Error with context: {"timestamp":"2025-09-18T19:25:43.074055","error_type":"OperationalError","error_message":"(2003, \"Can't connect to MySQL server on '127.0.0.1'\")","context":{"method":"initialize_database"}}
Traceback (most recent call last):
  File "C:\Users\victus\AppData\Local\Packages\PythonSoftwareFoundation.Python.3.13_qbz5n2kfra8p0\LocalCache\local-packages\Python313\site-packages\aiomysql\connection.py", line 527, in _connect
    self._reader, self._writer = await \
                                 ^^^^^^^
    ...<4 lines>...
            timeout=self.connect_timeout)
            ^^^^^^^^^^^^^^^^^^^^^^^^^^^^^
  File "C:\Program Files\WindowsApps\PythonSoftwareFoundation.Python.3.13_3.13.2032.0_x64__qbz5n2kfra8p0\Lib\asyncio\tasks.py", line 507, in wait_for
    return await fut
           ^^^^^^^^^
  File "C:\Users\victus\AppData\Local\Packages\PythonSoftwareFoundation.Python.3.13_qbz5n2kfra8p0\LocalCache\local-packages\Python313\site-packages\aiomysql\connection.py", line 88, in _open_connection
    transport, _ = await loop.create_connection(
                   ^^^^^^^^^^^^^^^^^^^^^^^^^^^^^
        lambda: protocol, host, port, **kwds)
        ^^^^^^^^^^^^^^^^^^^^^^^^^^^^^^^^^^^^^
  File "C:\Program Files\WindowsApps\PythonSoftwareFoundation.Python.3.13_3.13.2032.0_x64__qbz5n2kfra8p0\Lib\asyncio\base_events.py", line 1171, in create_connection
    raise exceptions[0]
  File "C:\Program Files\WindowsApps\PythonSoftwareFoundation.Python.3.13_3.13.2032.0_x64__qbz5n2kfra8p0\Lib\asyncio\base_events.py", line 1146, in create_connection
    sock = await self._connect_sock(
           ^^^^^^^^^^^^^^^^^^^^^^^^^
        exceptions, addrinfo, laddr_infos)
        ^^^^^^^^^^^^^^^^^^^^^^^^^^^^^^^^^^
  File "C:\Program Files\WindowsApps\PythonSoftwareFoundation.Python.3.13_3.13.2032.0_x64__qbz5n2kfra8p0\Lib\asyncio\base_events.py", line 1045, in _connect_sock
    await self.sock_connect(sock, address)
  File "C:\Program Files\WindowsApps\PythonSoftwareFoundation.Python.3.13_3.13.2032.0_x64__qbz5n2kfra8p0\Lib\asyncio\proactor_events.py", line 728, in sock_connect
    return await self._proactor.connect(sock, address)
           ^^^^^^^^^^^^^^^^^^^^^^^^^^^^^^^^^^^^^^^^^^^
  File "C:\Program Files\WindowsApps\PythonSoftwareFoundation.Python.3.13_3.13.2032.0_x64__qbz5n2kfra8p0\Lib\asyncio\windows_events.py", line 804, in _poll
    value = callback(transferred, key, ov)
  File "C:\Program Files\WindowsApps\PythonSoftwareFoundation.Python.3.13_3.13.2032.0_x64__qbz5n2kfra8p0\Lib\asyncio\windows_events.py", line 600, in finish_connect
    ov.getresult()
    ~~~~~~~~~~~~^^
ConnectionRefusedError: [WinError 1225] The remote computer refused the network connection

The above exception was the direct cause of the following exception:

Traceback (most recent call last):
  File "C:\Users\victus\Desktop\Main3.2\general\Database\MySQL\db_manager.py", line 29, in initialize
    self.pool = await aiomysql.create_pool(
                ^^^^^^^^^^^^^^^^^^^^^^^^^^^
    ...<16 lines>...
    )
    ^
  File "C:\Users\victus\AppData\Local\Packages\PythonSoftwareFoundation.Python.3.13_qbz5n2kfra8p0\LocalCache\local-packages\Python313\site-packages\aiomysql\pool.py", line 29, in _create_pool
    await pool._fill_free_pool(False)
  File "C:\Users\victus\AppData\Local\Packages\PythonSoftwareFoundation.Python.3.13_qbz5n2kfra8p0\LocalCache\local-packages\Python313\site-packages\aiomysql\pool.py", line 182, in _fill_free_pool
    conn = await connect(echo=self._echo, loop=self._loop,
           ^^^^^^^^^^^^^^^^^^^^^^^^^^^^^^^^^^^^^^^^^^^^^^^
                         **self._conn_kwargs)
                         ^^^^^^^^^^^^^^^^^^^^
  File "C:\Users\victus\AppData\Local\Packages\PythonSoftwareFoundation.Python.3.13_qbz5n2kfra8p0\LocalCache\local-packages\Python313\site-packages\aiomysql\connection.py", line 75, in _connect
    await conn._connect()
  File "C:\Users\victus\AppData\Local\Packages\PythonSoftwareFoundation.Python.3.13_qbz5n2kfra8p0\LocalCache\local-packages\Python313\site-packages\aiomysql\connection.py", line 563, in _connect
    raise OperationalError(
    ...<2 lines>...
    ) from e
pymysql.err.OperationalError: (2003, "Can't connect to MySQL server on '127.0.0.1'")
2025-09-18 22:55:43 - error_logger - ERROR - Error with context: {"timestamp":"2025-09-18T19:25:43.089684","error_type":"OperationalError","error_message":"(2003, \"Can't connect to MySQL server on '127.0.0.1'\")","context":{"phase":"initialization"}}
Traceback (most recent call last):
  File "C:\Users\victus\AppData\Local\Packages\PythonSoftwareFoundation.Python.3.13_qbz5n2kfra8p0\LocalCache\local-packages\Python313\site-packages\aiomysql\connection.py", line 527, in _connect
    self._reader, self._writer = await \
                                 ^^^^^^^
    ...<4 lines>...
            timeout=self.connect_timeout)
            ^^^^^^^^^^^^^^^^^^^^^^^^^^^^^
  File "C:\Program Files\WindowsApps\PythonSoftwareFoundation.Python.3.13_3.13.2032.0_x64__qbz5n2kfra8p0\Lib\asyncio\tasks.py", line 507, in wait_for
    return await fut
           ^^^^^^^^^
  File "C:\Users\victus\AppData\Local\Packages\PythonSoftwareFoundation.Python.3.13_qbz5n2kfra8p0\LocalCache\local-packages\Python313\site-packages\aiomysql\connection.py", line 88, in _open_connection
    transport, _ = await loop.create_connection(
                   ^^^^^^^^^^^^^^^^^^^^^^^^^^^^^
        lambda: protocol, host, port, **kwds)
        ^^^^^^^^^^^^^^^^^^^^^^^^^^^^^^^^^^^^^
  File "C:\Program Files\WindowsApps\PythonSoftwareFoundation.Python.3.13_3.13.2032.0_x64__qbz5n2kfra8p0\Lib\asyncio\base_events.py", line 1171, in create_connection
    raise exceptions[0]
  File "C:\Program Files\WindowsApps\PythonSoftwareFoundation.Python.3.13_3.13.2032.0_x64__qbz5n2kfra8p0\Lib\asyncio\base_events.py", line 1146, in create_connection
    sock = await self._connect_sock(
           ^^^^^^^^^^^^^^^^^^^^^^^^^
        exceptions, addrinfo, laddr_infos)
        ^^^^^^^^^^^^^^^^^^^^^^^^^^^^^^^^^^
  File "C:\Program Files\WindowsApps\PythonSoftwareFoundation.Python.3.13_3.13.2032.0_x64__qbz5n2kfra8p0\Lib\asyncio\base_events.py", line 1045, in _connect_sock
    await self.sock_connect(sock, address)
  File "C:\Program Files\WindowsApps\PythonSoftwareFoundation.Python.3.13_3.13.2032.0_x64__qbz5n2kfra8p0\Lib\asyncio\proactor_events.py", line 728, in sock_connect
    return await self._proactor.connect(sock, address)
           ^^^^^^^^^^^^^^^^^^^^^^^^^^^^^^^^^^^^^^^^^^^
  File "C:\Program Files\WindowsApps\PythonSoftwareFoundation.Python.3.13_3.13.2032.0_x64__qbz5n2kfra8p0\Lib\asyncio\windows_events.py", line 804, in _poll
    value = callback(transferred, key, ov)
  File "C:\Program Files\WindowsApps\PythonSoftwareFoundation.Python.3.13_3.13.2032.0_x64__qbz5n2kfra8p0\Lib\asyncio\windows_events.py", line 600, in finish_connect
    ov.getresult()
    ~~~~~~~~~~~~^^
ConnectionRefusedError: [WinError 1225] The remote computer refused the network connection

The above exception was the direct cause of the following exception:

Traceback (most recent call last):
  File "C:\Users\victus\Desktop\Main3.2\main.py", line 51, in initialize
    await self.db.initialize()
  File "C:\Users\victus\Desktop\Main3.2\general\Database\MySQL\db_manager.py", line 29, in initialize
    self.pool = await aiomysql.create_pool(
                ^^^^^^^^^^^^^^^^^^^^^^^^^^^
    ...<16 lines>...
    )
    ^
  File "C:\Users\victus\AppData\Local\Packages\PythonSoftwareFoundation.Python.3.13_qbz5n2kfra8p0\LocalCache\local-packages\Python313\site-packages\aiomysql\pool.py", line 29, in _create_pool
    await pool._fill_free_pool(False)
  File "C:\Users\victus\AppData\Local\Packages\PythonSoftwareFoundation.Python.3.13_qbz5n2kfra8p0\LocalCache\local-packages\Python313\site-packages\aiomysql\pool.py", line 182, in _fill_free_pool
    conn = await connect(echo=self._echo, loop=self._loop,
           ^^^^^^^^^^^^^^^^^^^^^^^^^^^^^^^^^^^^^^^^^^^^^^^
                         **self._conn_kwargs)
                         ^^^^^^^^^^^^^^^^^^^^
  File "C:\Users\victus\AppData\Local\Packages\PythonSoftwareFoundation.Python.3.13_qbz5n2kfra8p0\LocalCache\local-packages\Python313\site-packages\aiomysql\connection.py", line 75, in _connect
    await conn._connect()
  File "C:\Users\victus\AppData\Local\Packages\PythonSoftwareFoundation.Python.3.13_qbz5n2kfra8p0\LocalCache\local-packages\Python313\site-packages\aiomysql\connection.py", line 563, in _connect
    raise OperationalError(
    ...<2 lines>...
    ) from e
pymysql.err.OperationalError: (2003, "Can't connect to MySQL server on '127.0.0.1'")
2025-09-18 22:57:36 - error_logger - ERROR - Error with context: {"timestamp":"2025-09-18T19:27:36.686792","error_type":"ConnectionError","error_message":"Error 22 connecting to 127.0.0.1:6379. The remote computer refused the network connection.","context":{"operation":"redis_initialize"}}
Traceback (most recent call last):
  File "C:\Users\victus\AppData\Local\Packages\PythonSoftwareFoundation.Python.3.13_qbz5n2kfra8p0\LocalCache\local-packages\Python313\site-packages\redis\asyncio\connection.py", line 305, in connect_check_health
    await self.retry.call_with_retry(
        lambda: self._connect(), lambda error: self.disconnect()
    )
  File "C:\Users\victus\AppData\Local\Packages\PythonSoftwareFoundation.Python.3.13_qbz5n2kfra8p0\LocalCache\local-packages\Python313\site-packages\redis\asyncio\retry.py", line 50, in call_with_retry
    return await do()
           ^^^^^^^^^^
  File "C:\Users\victus\AppData\Local\Packages\PythonSoftwareFoundation.Python.3.13_qbz5n2kfra8p0\LocalCache\local-packages\Python313\site-packages\redis\asyncio\connection.py", line 760, in _connect
    reader, writer = await asyncio.open_connection(
                     ^^^^^^^^^^^^^^^^^^^^^^^^^^^^^^
        **self._connection_arguments()
        ^^^^^^^^^^^^^^^^^^^^^^^^^^^^^^
    )
    ^
  File "C:\Program Files\WindowsApps\PythonSoftwareFoundation.Python.3.13_3.13.2032.0_x64__qbz5n2kfra8p0\Lib\asyncio\streams.py", line 48, in open_connection
    transport, _ = await loop.create_connection(
                   ^^^^^^^^^^^^^^^^^^^^^^^^^^^^^
        lambda: protocol, host, port, **kwds)
        ^^^^^^^^^^^^^^^^^^^^^^^^^^^^^^^^^^^^^
  File "C:\Program Files\WindowsApps\PythonSoftwareFoundation.Python.3.13_3.13.2032.0_x64__qbz5n2kfra8p0\Lib\asyncio\base_events.py", line 1171, in create_connection
    raise exceptions[0]
  File "C:\Program Files\WindowsApps\PythonSoftwareFoundation.Python.3.13_3.13.2032.0_x64__qbz5n2kfra8p0\Lib\asyncio\base_events.py", line 1146, in create_connection
    sock = await self._connect_sock(
           ^^^^^^^^^^^^^^^^^^^^^^^^^
        exceptions, addrinfo, laddr_infos)
        ^^^^^^^^^^^^^^^^^^^^^^^^^^^^^^^^^^
  File "C:\Program Files\WindowsApps\PythonSoftwareFoundation.Python.3.13_3.13.2032.0_x64__qbz5n2kfra8p0\Lib\asyncio\base_events.py", line 1045, in _connect_sock
    await self.sock_connect(sock, address)
  File "C:\Program Files\WindowsApps\PythonSoftwareFoundation.Python.3.13_3.13.2032.0_x64__qbz5n2kfra8p0\Lib\asyncio\proactor_events.py", line 728, in sock_connect
    return await self._proactor.connect(sock, address)
           ^^^^^^^^^^^^^^^^^^^^^^^^^^^^^^^^^^^^^^^^^^^
  File "C:\Program Files\WindowsApps\PythonSoftwareFoundation.Python.3.13_3.13.2032.0_x64__qbz5n2kfra8p0\Lib\asyncio\windows_events.py", line 804, in _poll
    value = callback(transferred, key, ov)
  File "C:\Program Files\WindowsApps\PythonSoftwareFoundation.Python.3.13_3.13.2032.0_x64__qbz5n2kfra8p0\Lib\asyncio\windows_events.py", line 600, in finish_connect
    ov.getresult()
    ~~~~~~~~~~~~^^
ConnectionRefusedError: [WinError 1225] The remote computer refused the network connection

During handling of the above exception, another exception occurred:

Traceback (most recent call last):
  File "C:\Users\victus\Desktop\Main3.2\general\Caching\redis_service.py", line 55, in initialize
    await self.redis.ping()
  File "C:\Users\victus\AppData\Local\Packages\PythonSoftwareFoundation.Python.3.13_qbz5n2kfra8p0\LocalCache\local-packages\Python313\site-packages\redis\asyncio\client.py", line 672, in execute_command
    conn = self.connection or await pool.get_connection()
                              ^^^^^^^^^^^^^^^^^^^^^^^^^^^
  File "C:\Users\victus\AppData\Local\Packages\PythonSoftwareFoundation.Python.3.13_qbz5n2kfra8p0\LocalCache\local-packages\Python313\site-packages\redis\asyncio\connection.py", line 1149, in get_connection
    await self.ensure_connection(connection)
  File "C:\Users\victus\AppData\Local\Packages\PythonSoftwareFoundation.Python.3.13_qbz5n2kfra8p0\LocalCache\local-packages\Python313\site-packages\redis\asyncio\connection.py", line 1182, in ensure_connection
    await connection.connect()
  File "C:\Users\victus\AppData\Local\Packages\PythonSoftwareFoundation.Python.3.13_qbz5n2kfra8p0\LocalCache\local-packages\Python313\site-packages\redis\asyncio\connection.py", line 296, in connect
    await self.connect_check_health(check_health=True)
  File "C:\Users\victus\AppData\Local\Packages\PythonSoftwareFoundation.Python.3.13_qbz5n2kfra8p0\LocalCache\local-packages\Python313\site-packages\redis\asyncio\connection.py", line 315, in connect_check_health
    raise ConnectionError(self._error_message(e))
redis.exceptions.ConnectionError: Error 22 connecting to 127.0.0.1:6379. The remote computer refused the network connection.
